ERROR:root:Error 204 while calling http://www.viaggiatreno.it/infomobilita/resteasy/viaggiatreno/andamentoTreno/S01700/679/1702249200000: 
Traceback (most recent call last):
  File "/Users/matteodelton/Developer/OrarioTreni/src/trains.py", line 476, in <module>
    station.showArrivals()
  File "/Users/matteodelton/Developer/OrarioTreni/src/trains.py", line 360, in showArrivals
    for (train, journey) in zip(arrivals, futures, strict=True):
  File "/usr/local/Cellar/python@3.12/3.12.1/Frameworks/Python.framework/Versions/3.12/lib/python3.12/concurrent/futures/_base.py", line 619, in result_iterator
    yield _result_or_cancel(fs.pop())
          ^^^^^^^^^^^^^^^^^^^^^^^^^^^
  File "/usr/local/Cellar/python@3.12/3.12.1/Frameworks/Python.framework/Versions/3.12/lib/python3.12/concurrent/futures/_base.py", line 317, in _result_or_cancel
    return fut.result(timeout)
           ^^^^^^^^^^^^^^^^^^^
  File "/usr/local/Cellar/python@3.12/3.12.1/Frameworks/Python.framework/Versions/3.12/lib/python3.12/concurrent/futures/_base.py", line 449, in result
    return self.__get_result()
           ^^^^^^^^^^^^^^^^^^^
  File "/usr/local/Cellar/python@3.12/3.12.1/Frameworks/Python.framework/Versions/3.12/lib/python3.12/concurrent/futures/_base.py", line 401, in __get_result
    raise self._exception
  File "/usr/local/Cellar/python@3.12/3.12.1/Frameworks/Python.framework/Versions/3.12/lib/python3.12/concurrent/futures/thread.py", line 58, in run
    result = self.fn(*self.args, **self.kwargs)
             ^^^^^^^^^^^^^^^^^^^^^^^^^^^^^^^^^^
  File "/Users/matteodelton/Developer/OrarioTreni/src/trains.py", line 185, in fromTrain
    return cls(train.origin_station, train.number, train.departure_date)
           ^^^^^^^^^^^^^^^^^^^^^^^^^^^^^^^^^^^^^^^^^^^^^^^^^^^^^^^^^^^^^
  File "/Users/matteodelton/Developer/OrarioTreni/src/trains.py", line 167, in __init__
    raise Exception('Trenitalia non sta fornendo aggiornamenti')
Exception: Trenitalia non sta fornendo aggiornamenti
